Workbook
Name Discount_Table: 'Master Sheet'!$B$2:$C$12
Name NativeTimeline_Order_Date1: #N/A
Name Product_Assign: 'Master Sheet'!$E$3:$F$9
Name Region_Table: 'Master Sheet'!$E$16:$F$22
Name Slicer_Brand_Name: #N/A
Name Slicer_City: #N/A
Name Slicer_Dealer_Name1: #N/A
Name Slicer_Region1: #N/A
Name Slicer_State: #N/A
Name Slicer_Tractor_Model: #N/A
Name Table_2: Table1[#All]

Sheet Raw_Sales_Data
A1: Invoice ID | B1: Order Date | C1: Dealer Name | D1: State | E1: City | F1: Region | G1: Sales Executive | H1: Tractor Model | I1: Quantity | J1: Unit Price | K1: Discount % | L1: Sales Amount | M1: Payment Status | N1: Delivery Status | O1: GST Status | P1: Order Status
A2: INV1000 | B2: 2024/04/23 | C2: Shakti Agro | D2: UP | E2: Lucknow | F2: North | G2: NEHA | H2: Farmtrac 60 | I2: 1 | J2: 810386 | K2: 0 | L2: 810386 | M2: Partial | N2: Cancelled | O2: Invalid | P2: Cancelled
A3: INV1001 | B3: 2024/02/04 | C3: Shakti Agro | D3: Karnataka | E3: Bengaluru | F3: South | G3: Priya | H3: Kubota MU4501 | I3: 6 | J3: 421642 | K3: 5 | L3: 2403359.4 | M3: Partial | N3: Cancelled | O3: Invalid | P3: Cancelled
A4: INV1002 | B4: 2024/12/31 | C4: Green Field | D4: Maharashtra | E4: Pune | F4: West | G4: Amit | H4: Kubota MU4501 | I4: 7 | J4: 58962 | K4: 0 | L4: 412734 | M4: Pending | N4: Delivered | O4: Valid | P4: Cancelled
A5: INV1003 | B5: 09/15/2024 | C5: Green Field | D5: Haryana | E5: Gurugram | F5: North | G5: Priya | H5: Kubota MU4501 | I5: 7 | J5: 640018 | K5: 10 | L5: 4032113.4 | M5: Partial | N5: Delivered | O5: Valid | P5: Pending
A6: INV1004 | B6: 28-05-2025 | C6: Shakti Agro | D6: haryana | E6: Gurugram | F6: North | G6: Neha | H6: Farmtrac 45 | I6: 2 | J6: 736528 | K6: 10 | L6: 1325750.4 | M6: Paid | N6: Delivered | O6: Invalid | P6: Completed
A7: INV1005 | B7: 27-03-2025 | C7: Green Field | D7: UP | E7: Lucknow | F7: North | G7: Amit | H7: Powertrac 439 | I7: 3 | J7: 446618 | K7: 2 | L7: 1313056.9 | M7: Pending | N7: Delivered | O7: Invalid | P7: Completed
A8: INV1006 | B8: 09-10-2024 | C8: Green Field | D8: Maharashtra | E8: Pune | F8: West | G8: Vikas | H8: Powertrac 439 | I8: 4 | J8: 636846 | K8: 7 | L8: 2369067.1 | M8: Partial | N8: Delivered | O8: Invalid | P8: Cancelled
A9: INV1007 | B9: 17-11-2024 | C9: Kisan Tractors | D9: West Bengal | E9: Kolkata | F9: East | G9: Neha | H9: Farmtrac 45 | I9: 4 | J9: 87171 | K9: 5 | L9: 331249.8 | M9: Pending | N9: In Transit | O9: Valid | P9: Completed
A10: INV1008 | B10: 09-11-2024 | C10: Kisan Tractors | D10: Haryana | E10: Gurugram | F10: North | G10: Rohit | H10: Kubota MU4501 | I10: 6 | J10: 435799 | K10: 7 | L10: 2431758.4 | M10: Paid | N10: Delivered | O10: Valid | P10: Completed
A11: INV1009 | B11: 23-11-2024 | C11: Mahadev Motors | D11: Karnataka | E11: Bengaluru | F11: South | G11: Priya | H11: Farmtrac 45 | I11: 3 | J11: 91771 | K11: 12 | L11: 242275.44 | M11: Paid | N11: In Transit | O11: Valid | P11: Cancelled
A12: INV1010 | B12: 2024/02/07 | C12: Mahadev Motors | D12: UP | E12: Lucknow | F12: North | G12: NEHA | H12: Powertrac 439 | I12: 1 | J12: 366788 | K12: 2 | L12: 359452.24 | M12: Partial | N12: In Transit | O12: Invalid | P12: Completed
A13: INV1011 | B13: 16-01-2025 | C13: Kisan Tractors | D13: West Bengal | E13: Kolkata | F13: East | G13: Rohit | H13: Powertrac 439 | I13: 8 | J13: 745852 | K13: 0 | L13: 5966816 | M13: Paid | N13: Delivered | O13: Valid | P13: Pending
... A61: INV1059 | B61: 08/21/2024 | C61: Shakti Agro | D61: UP | E61: Lucknow | F61: North | G61: Priya | H61: Powertrac 439 | I61: 5 | J61: 501803 | K61: 2 | L61: 2458834.7 | M61: Paid | N61: Delivered | O61: Valid | P61: Pending
A62: INV1060 | B62: 12/15/2024 | C62: Agri Motors | D62: Haryana | E62: Gurugram | F62: North | G62: ROHIT | H62: Farmtrac 60 | J62: 652887 | K62: 10 | M62: Partial | N62: Delivered | O62: Invalid | P62: Completed
A63: INV1061 | B63: 2024/07/21 | C63: Shakti Agro | D63: Maharashtra | E63: Pune | F63: West | G63: VIKAS | H63: Kubota NeoStar | J63: 526133 | K63: 10 | M63: Pending | N63: Cancelled | O63: Invalid | P63: Pending
A64: INV1062 | B64: 04-01-2025 | C64: Green Field | D64: Haryana | E64: Gurugram | F64: North | G64: Vikas | H64: Powertrac 439 | I64: 5 | J64: 711154 | K64: 0 | L64: 3555770 | M64: Paid | N64: Delivered | O64: Valid | P64: Completed
A65: INV1063 | B65: 2024/11/06 | C65: Shakti Agro | D65: Haryana | E65: Gurugram | F65: North | G65: Priya | H65: Farmtrac 45 | I65: 4 | J65: 105885 | K65: 2 | L65: 415069.2 | M65: Pending | N65: Delivered | O65: Invalid | P65: Pending
A66: INV1064 | B66: 17-10-2024 | C66: Agri Motors | D66: West Bengal | E66: Kolkata | F66: East | G66: Vikas | H66: Farmtrac 60 | I66: 1 | J66: 618459 | K66: 5 | L66: 587536.05 | M66: Pending | N66: Delivered | O66: Invalid | P66: Completed
A67: INV1065 | B67: 10/18/2024 | C67: Agri Motors | D67: West Bengal | E67: Kolkata | F67: East | G67: Priya | H67: Farmtrac 45 | I67: 6 | J67: 74760 | K67: 12 | L67: 394732.8 | M67: Pending | N67: Delivered | O67: Invalid | P67: Cancelled
A68: INV1066 | B68: 08-02-2025 | C68: Mahadev Motors | D68: Karnataka | E68: Bengaluru | F68: South | G68: Neha | H68: Farmtrac 45 | I68: 5 | J68: 50674 | K68: 7 | L68: 235634.1 | M68: Partial | N68: Cancelled | O68: Invalid | P68: Pending
A69: INV1067 | B69: 06/21/2025 | C69: Shakti Agro | D69: Maharashtra | E69: Pune | F69: West | G69: Neha | H69: Kubota MU4501 | I69: 2 | J69: 832128 | K69: 5 | L69: 1581043.2 | M69: Pending | N69: In Transit | O69: Invalid | P69: Cancelled
A70: INV1068 | B70: 12/02/2024 | C70: Kisan Tractors | D70: Maharashtra | E70: Pune | F70: West | G70: Rohit | H70: Kubota MU4501 | I70: 4 | J70: 866057 | K70: 5 | L70: 3291016.6 | M70: Paid | N70: In Transit | O70: Valid | P70: Pending
A71: INV1069 | B71: 16-02-2024 | C71: Kisan Tractors | D71: Maharashtra | E71: Pune | F71: West | G71: Neha | H71: Farmtrac 45 | I71: 3 | J71: 653046 | K71: 0 | L71: 1959138 | M71: Pending | N71: In Transit | O71: Valid | P71: Pending
A72: INV1070 | B72: 2025/06/14 | C72: Shakti Agro | D72: Maharashtra | E72: Pune | F72: West | G72: Rohit | H72: Farmtrac 45 | I72: 7 | J72: 516456 | K72: 12 | L72: 3181369 | M72: Paid | N72: Cancelled | O72: Valid | P72: Completed
A73: INV1071 | B73: 11/21/2024 | C73: Agri Motors | D73: west bengal | E73: Kolkata | F73: East | G73: Amit | H73: Powertrac 439 | I73: 4 | J73: 745689 | K73: 5 | L73: 2833618.2 | M73: Partial | N73: Cancelled | O73: Invalid | P73: Pending
A74: INV1072 | B74: 2024/01/27 | C74: Kisan Tractors | D74: haryana | E74: Gurugram | F74: North | G74: Rohit | H74: Powertrac 439 | I74: 5 | J74: 127757 | M74: Pending | N74: Cancelled | O74: Invalid | P74: Pending
A75: INV1073 | B75: 19-11-2024 | C75: Mahadev Motors | D75: West Bengal | E75: Kolkata | F75: East | G75: Rohit | H75: Farmtrac 60 | I75: 8 | J75: 260553 | K75: 10 | L75: 1875981.6 | M75: Pending | N75: In Transit | O75: Invalid | P75: Completed
A76: INV1074 | B76: 04/25/2025 | C76: Agri Motors | D76: UP | E76: Lucknow | F76: North | G76: Amit | H76: Kubota MU4501 | I76: 2 | J76: 420146 | K76: 2 | L76: 823486.16 | M76: Paid | N76: In Transit | O76: Invalid | P76: Pending
A77: INV1075 | B77: 04/21/2024 | C77: Agri Motors | D77: UP | E77: Lucknow | F77: North | G77: Rohit | H77: Farmtrac 60 | I77: 8 | J77: 267590 | K77: 7 | L77: 1990869.6 | M77: Paid | N77: In Transit | O77: Invalid | P77: Pending
A78: INV1076 | B78: 09/23/2024 | C78: Mahadev Motors | D78: West Bengal | E78: Kolkata | F78: East | G78: Rohit | H78: Kubota MU4501 | I78: 8 | J78: 100872 | K78: 0 | L78: 806976 | M78: Partial | N78: Delivered | O78: Valid | P78: Pending
A79: INV1077 | B79: 05-04-2025 | C79: Green Field | D79: haryana | E79: Gurugram | F79: North | G79: Rohit | H79: Farmtrac 45 | I79: 6 | J79: 103288 | K79: 2 | L79: 607333.44 | M79: Partial | N79: Delivered | O79: Valid | P79: Cancelled
A80: INV1078 | B80: 2024/10/23 | C80: Mahadev Motors | D80: Haryana | E80: Gurugram | F80: North | G80: Neha | H80: Farmtrac 60 | I80: 5 | J80: 804507 | K80: 2 | L80: 3942084.3 | M80: Partial | N80: In Transit | O80: Valid | P80: Pending
A81: INV1079 | B81: 2024/04/23 | C81: Shakti Agro | D81: UP | E81: Lucknow | F81: North | G81: Rohit | H81: Kubota MU4501 | J81: 171346 | K81: 12 | M81: Pending | N81: Cancelled | O81: Invalid | P81: Pending
A82: INV1080 | B82: 2024/03/15 | C82: Agri Motors | D82: Maharashtra | E82: Pune | F82: West | G82: PRIYA | H82: Kubota NeoStar | I82: 2 | J82: 854924 | K82: 0 | L82: 1709848 | M82: Partial | N82: Cancelled | O82: Invalid | P82: Pending
A83: INV1081 | B83: 02/14/2024 | C83: Mahadev Motors | D83: Karnataka | E83: Bengaluru | F83: South | G83: Neha | H83: Farmtrac 60 | I83: 5 | J83: 258706 | K83: 12 | L83: 1138306.4 | M83: Paid | N83: Delivered | O83: Invalid | P83: Cancelled
A84: INV1082 | B84: 01/14/2024 | C84: Green Field | D84: Haryana | E84: Gurugram | F84: North | G84: Vikas | H84: Powertrac 439 | I84: 3 | J84: 512291 | K84: 0 | L84: 1536873 | M84: Paid | N84: Delivered | O84: Valid | P84: Cancelled
A85: INV1083 | B85: 11/14/2024 | C85: Kisan Tractors | D85: West Bengal | E85: Kolkata | F85: East | G85: Neha | H85: Farmtrac 45 | I85: 8 | J85: 173310 | K85: 10 | L85: 1247832 | M85: Paid | N85: In Transit | O85: Valid | P85: Pending
A86: INV1084 | B86: 02-04-2024 | C86: Green Field | D86: West Bengal | E86: Kolkata | F86: East | G86: Neha | H86: Kubota MU4501 | I86: 6 | J86: 237351 | K86: 12 | L86: 1253213.3 | M86: Partial | N86: Cancelled | O86: Invalid | P86: Completed
A87: INV1085 | B87: 03/28/2025 | C87: Shakti Agro | D87: UP | E87: Lucknow | F87: North | G87: PRIYA | H87: Farmtrac 45 | I87: 7 | J87: 210905 | K87: 7 | L87: 1372991.6 | M87: Paid | N87: Delivered | O87: Valid | P87: Pending
...

Sheet Master Sheet
B2: Discount (%) Allotment Table
B3: Tractor Quantity Purchased | C3: Discount Allotment | E3: Product Category Assignment
B4: 0 | C4: 0 | E4: Product Model | F4: Product Category
B5: 1 | C5: 3 | E5: Farmtrac 60 | F5: Farmtrac
B6: 2 | C6: 5 | E6: Kubota Mu4501 | F6: Kubota
B7: 3 | C7: 6 | E7: Farmtrac 45 | F7: Farmtrac
B8: 4 | C8: 6 | E8: Powertrac 439 | F8: Powertrac
B9: 5 | C9: 7 | E9: Kubota Neostar | F9: Kubota
B10: 6 | C10: 8
B11: 7 | C11: 9
B12: 8 | C12: 9
B16: Average of Discount % | E16: Region Table
B17: 6.482567 | E17: City Name | F17: Region
E18: Lucknow | F18: North
E19: Bengaluru | F19: South
E20: Pune | F20: West
E21: Gurugram | F21: North
E22: Kolkata | F22: East

Sheet Cleaned Data
A1: Invoice ID | B1: Order Date | C1: Sales Executive | D1: Dealer Name | E1: State | F1: Dealer Master Key | G1: City | H1: Region | I1: Tractor Model | J1: Brand Name | K1: Quantity | L1: Unit Price | M1: Discount % | N1: Gross Amount | O1: Gross Amount (Cr) | P1: Net Sales Amount | Q1: Net Sales (Cr) | R1: Payment Status | S1: Delivery Status | T1: GST Status | U1: Order Status
A2: INV1000 | B2: 45405 | C2: Neha | D2: Shakti | E2: Uttar Pradesh | F2: Shakti Agro Uttar Pradesh | G2: Lucknow | H2: =VLOOKUP(Table1[[#This Row],[City]],Table6[#All],2,FALSE) -> North | I2: Farmtrac 60 | J2: =_xlfn.XLOOKUP(Table1[[#This Row],[Tractor Model]],Table7[Product Model],Table7[Product Category],"Not Available",0) -> Farmtrac | K2: 1 | L2: 810386 | M2: =INDEX('Master Sheet'!$C$4:$C$12,MATCH(Table1[[#This Row],[Quantity]],'Master Sheet'!$B$4:$B$12,0)) -> 3 | N2: =Table1[[#This Row],[Quantity]]*Table1[[#This Row],[Unit Price]] -> 810386 | O2: 0.0810386 | P2: =Table1[[#This Row],[Gross Amount]]*(1-(Table1[[#This Row],[Discount %]]/100)) -> 786074.42 | Q2: =(Table1[[#This Row],[Gross Amount]]*(1-(Table1[[#This Row],[Discount %]]/100)))/10000000 -> 0.078607442 | R2: Partial | S2: {=IFERROR(_xlfn.IFS(Table1[[#This Row],[Payment Status]]="Partial","In Transit",Table1[[#This Row],[Payment Status]]="Paid","Delivered",Table1[[#This Row],[Payment Status]]="Pending","Pending"),"Invalid Input")} -> In Transit | T2: Invalid | U2: {=IFERROR(_xlfn.IFS(Table1[[#This Row],[Payment Status]]="Partial","In Transit",Table1[[#This Row],[Payment Status]]="Paid","Completed",Table1[[#This Row],[Payment Status]]="Pending","Pending"),"Invalid Input")} -> In Transit
A3: INV1001 | B3: 45326 | C3: Priya | D3: Shakti | E3: Karnataka | F3: Shakti Agro Karnataka | G3: Bengaluru | H3: =VLOOKUP(Table1[[#This Row],[City]],Table6[#All],2,FALSE) -> South | I3: Kubota Mu4501 | J3: =_xlfn.XLOOKUP(Table1[[#This Row],[Tractor Model]],Table7[Product Model],Table7[Product Category],"Not Available",0) -> Kubota | K3: 6 | L3: 421642 | M3: =INDEX('Master Sheet'!$C$4:$C$12,MATCH(Table1[[#This Row],[Quantity]],'Master Sheet'!$B$4:$B$12,0)) -> 8 | N3: =Table1[[#This Row],[Quantity]]*Table1[[#This Row],[Unit Price]] -> 2529852 | O3: 0.2529852 | P3: =Table1[[#This Row],[Gross Amount]]*(1-(Table1[[#This Row],[Discount %]]/100)) -> 2327463.8 | Q3: =(Table1[[#This Row],[Gross Amount]]*(1-(Table1[[#This Row],[Discount %]]/100)))/10000000 -> 0.23274638 | R3: Partial | S3: {=IFERROR(_xlfn.IFS(Table1[[#This Row],[Payment Status]]="Partial","In Transit",Table1[[#This Row],[Payment Status]]="Paid","Delivered",Table1[[#This Row],[Payment Status]]="Pending","Pending"),"Invalid Input")} -> In Transit | T3: Invalid | U3: {=IFERROR(_xlfn.IFS(Table1[[#This Row],[Payment Status]]="Partial","In Transit",Table1[[#This Row],[Payment Status]]="Paid","Completed",Table1[[#This Row],[Payment Status]]="Pending","Pending"),"Invalid Input")} -> In Transit
A4: INV1002 | B4: 45657 | C4: Amit | D4: Green Field | E4: Maharashtra | F4: Green Field Maharashtra | G4: Pune | H4: =VLOOKUP(Table1[[#This Row],[City]],Table6[#All],2,FALSE) -> West | I4: Kubota Mu4501 | J4: =_xlfn.XLOOKUP(Table1[[#This Row],[Tractor Model]],Table7[Product Model],Table7[Product Category],"Not Available",0) -> Kubota | K4: 7 | L4: 58962 | M4: =INDEX('Master Sheet'!$C$4:$C$12,MATCH(Table1[[#This Row],[Quantity]],'Master Sheet'!$B$4:$B$12,0)) -> 9 | N4: =Table1[[#This Row],[Quantity]]*Table1[[#This Row],[Unit Price]] -> 412734 | O4: 0.0412734 | P4: =Table1[[#This Row],[Gross Amount]]*(1-(Table1[[#This Row],[Discount %]]/100)) -> 375587.94 | Q4: =(Table1[[#This Row],[Gross Amount]]*(1-(Table1[[#This Row],[Discount %]]/100)))/10000000 -> 0.037558794 | R4: Pending | S4: {=IFERROR(_xlfn.IFS(Table1[[#This Row],[Payment Status]]="Partial","In Transit",Table1[[#This Row],[Payment Status]]="Paid","Delivered",Table1[[#This Row],[Payment Status]]="Pending","Pending"),"Invalid Input")} -> Pending | T4: Invalid | U4: {=IFERROR(_xlfn.IFS(Table1[[#This Row],[Payment Status]]="Partial","In Transit",Table1[[#This Row],[Payment Status]]="Paid","Completed",Table1[[#This Row],[Payment Status]]="Pending","Pending"),"Invalid Input")} -> Pending
A5: INV1003 | B5: 45550 | C5: Priya | D5: Green Field | E5: Haryana | F5: Green Field Haryana | G5: Gurugram | H5: =VLOOKUP(Table1[[#This Row],[City]],Table6[#All],2,FALSE) -> North | I5: Kubota Mu4501 | J5: =_xlfn.XLOOKUP(Table1[[#This Row],[Tractor Model]],Table7[Product Model],Table7[Product Category],"Not Available",0) -> Kubota | K5: 7 | L5: 640018 | M5: =INDEX('Master Sheet'!$C$4:$C$12,MATCH(Table1[[#This Row],[Quantity]],'Master Sheet'!$B$4:$B$12,0)) -> 9 | N5: =Table1[[#This Row],[Quantity]]*Table1[[#This Row],[Unit Price]] -> 4480126 | O5: 0.4480126 | P5: =Table1[[#This Row],[Gross Amount]]*(1-(Table1[[#This Row],[Discount %]]/100)) -> 4076914.7 | Q5: =(Table1[[#This Row],[Gross Amount]]*(1-(Table1[[#This Row],[Discount %]]/100)))/10000000 -> 0.40769147 | R5: Partial | S5: {=IFERROR(_xlfn.IFS(Table1[[#This Row],[Payment Status]]="Partial","In Transit",Table1[[#This Row],[Payment Status]]="Paid","Delivered",Table1[[#This Row],[Payment Status]]="Pending","Pending"),"Invalid Input")} -> In Transit | T5: Invalid | U5: {=IFERROR(_xlfn.IFS(Table1[[#This Row],[Payment Status]]="Partial","In Transit",Table1[[#This Row],[Payment Status]]="Paid","Completed",Table1[[#This Row],[Payment Status]]="Pending","Pending"),"Invalid Input")} -> In Transit
A6: INV1004 | B6: 45805 | C6: Neha | D6: Shakti | E6: Haryana | F6: Shakti Agro Haryana | G6: Gurugram | H6: =VLOOKUP(Table1[[#This Row],[City]],Table6[#All],2,FALSE) -> North | I6: Farmtrac 45 | J6: =_xlfn.XLOOKUP(Table1[[#This Row],[Tractor Model]],Table7[Product Model],Table7[Product Category],"Not Available",0) -> Farmtrac | K6: 2 | L6: 736528 | M6: =INDEX('Master Sheet'!$C$4:$C$12,MATCH(Table1[[#This Row],[Quantity]],'Master Sheet'!$B$4:$B$12,0)) -> 5 | N6: =Table1[[#This Row],[Quantity]]*Table1[[#This Row],[Unit Price]] -> 1473056 | O6: 0.1473056 | P6: =Table1[[#This Row],[Gross Amount]]*(1-(Table1[[#This Row],[Discount %]]/100)) -> 1399403.2 | Q6: =(Table1[[#This Row],[Gross Amount]]*(1-(Table1[[#This Row],[Discount %]]/100)))/10000000 -> 0.13994032 | R6: Paid | S6: {=IFERROR(_xlfn.IFS(Table1[[#This Row],[Payment Status]]="Partial","In Transit",Table1[[#This Row],[Payment Status]]="Paid","Delivered",Table1[[#This Row],[Payment Status]]="Pending","Pending"),"Invalid Input")} -> Delivered | T6: Valid | U6: {=IFERROR(_xlfn.IFS(Table1[[#This Row],[Payment Status]]="Partial","In Transit",Table1[[#This Row],[Payment Status]]="Paid","Completed",Table1[[#This Row],[Payment Status]]="Pending","Pending"),"Invalid Input")} -> Completed
A7: INV1005 | B7: 45743 | C7: Amit | D7: Green Field | E7: Uttar Pradesh | F7: Green Field Uttar Pradesh | G7: Lucknow | H7: =VLOOKUP(Table1[[#This Row],[City]],Table6[#All],2,FALSE) -> North | I7: Powertrac 439 | J7: =_xlfn.XLOOKUP(Table1[[#This Row],[Tractor Model]],Table7[Product Model],Table7[Product Category],"Not Available",0) -> Powertrac | K7: 3 | L7: 446618 | M7: =INDEX('Master Sheet'!$C$4:$C$12,MATCH(Table1[[#This Row],[Quantity]],'Master Sheet'!$B$4:$B$12,0)) -> 6 | N7: =Table1[[#This Row],[Quantity]]*Table1[[#This Row],[Unit Price]] -> 1339854 | O7: 0.1339854 | P7: =Table1[[#This Row],[Gross Amount]]*(1-(Table1[[#This Row],[Discount %]]/100)) -> 1259462.8 | Q7: =(Table1[[#This Row],[Gross Amount]]*(1-(Table1[[#This Row],[Discount %]]/100)))/10000000 -> 0.12594628 | R7: Pending | S7: {=IFERROR(_xlfn.IFS(Table1[[#This Row],[Payment Status]]="Partial","In Transit",Table1[[#This Row],[Payment Status]]="Paid","Delivered",Table1[[#This Row],[Payment Status]]="Pending","Pending"),"Invalid Input")} -> Pending | T7: Valid | U7: {=IFERROR(_xlfn.IFS(Table1[[#This Row],[Payment Status]]="Partial","In Transit",Table1[[#This Row],[Payment Status]]="Paid","Completed",Table1[[#This Row],[Payment Status]]="Pending","Pending"),"Invalid Input")} -> Pending
A8: INV1006 | B8: 45574 | C8: Vikas | D8: Green Field | E8: Maharashtra | F8: Green Field Maharashtra | G8: Pune | H8: =VLOOKUP(Table1[[#This Row],[City]],Table6[#All],2,FALSE) -> West | I8: Powertrac 439 | J8: =_xlfn.XLOOKUP(Table1[[#This Row],[Tractor Model]],Table7[Product Model],Table7[Product Category],"Not Available",0) -> Powertrac | K8: 4 | L8: 636846 | M8: =INDEX('Master Sheet'!$C$4:$C$12,MATCH(Table1[[#This Row],[Quantity]],'Master Sheet'!$B$4:$B$12,0)) -> 6 | N8: =Table1[[#This Row],[Quantity]]*Table1[[#This Row],[Unit Price]] -> 2547384 | O8: 0.2547384 | P8: =Table1[[#This Row],[Gross Amount]]*(1-(Table1[[#This Row],[Discount %]]/100)) -> 2394541 | Q8: =(Table1[[#This Row],[Gross Amount]]*(1-(Table1[[#This Row],[Discount %]]/100)))/10000000 -> 0.2394541 | R8: Partial | S8: {=IFERROR(_xlfn.IFS(Table1[[#This Row],[Payment Status]]="Partial","In Transit",Table1[[#This Row],[Payment Status]]="Paid","Delivered",Table1[[#This Row],[Payment Status]]="Pending","Pending"),"Invalid Input")} -> In Transit | T8: Invalid | U8: {=IFERROR(_xlfn.IFS(Table1[[#This Row],[Payment Status]]="Partial","In Transit",Table1[[#This Row],[Payment Status]]="Paid","Completed",Table1[[#This Row],[Payment Status]]="Pending","Pending"),"Invalid Input")} -> In Transit
A9: INV1007 | B9: 45613 | C9: Neha | D9: Kisan | E9: West Bengal | F9: Kisan Tractors West Bengal | G9: Kolkata | H9: =VLOOKUP(Table1[[#This Row],[City]],Table6[#All],2,FALSE) -> East | I9: Farmtrac 45 | J9: =_xlfn.XLOOKUP(Table1[[#This Row],[Tractor Model]],Table7[Product Model],Table7[Product Category],"Not Available",0) -> Farmtrac | K9: 4 | L9: 87171 | M9: =INDEX('Master Sheet'!$C$4:$C$12,MATCH(Table1[[#This Row],[Quantity]],'Master Sheet'!$B$4:$B$12,0)) -> 6 | N9: =Table1[[#This Row],[Quantity]]*Table1[[#This Row],[Unit Price]] -> 348684 | O9: 0.0348684 | P9: =Table1[[#This Row],[Gross Amount]]*(1-(Table1[[#This Row],[Discount %]]/100)) -> 327762.96 | Q9: =(Table1[[#This Row],[Gross Amount]]*(1-(Table1[[#This Row],[Discount %]]/100)))/10000000 -> 0.032776296 | R9: Pending | S9: {=IFERROR(_xlfn.IFS(Table1[[#This Row],[Payment Status]]="Partial","In Transit",Table1[[#This Row],[Payment Status]]="Paid","Delivered",Table1[[#This Row],[Payment Status]]="Pending","Pending"),"Invalid Input")} -> Pending | T9: Valid | U9: {=IFERROR(_xlfn.IFS(Table1[[#This Row],[Payment Status]]="Partial","In Transit",Table1[[#This Row],[Payment Status]]="Paid","Completed",Table1[[#This Row],[Payment Status]]="Pending","Pending"),"Invalid Input")} -> Pending
A10: INV1008 | B10: 45605 | C10: Rohit | D10: Kisan | E10: Haryana | F10: Kisan Tractors Haryana | G10: Gurugram | H10: =VLOOKUP(Table1[[#This Row],[City]],Table6[#All],2,FALSE) -> North | I10: Kubota Mu4501 | J10: =_xlfn.XLOOKUP(Table1[[#This Row],[Tractor Model]],Table7[Product Model],Table7[Product Category],"Not Available",0) -> Kubota | K10: 6 | L10: 435799 | M10: =INDEX('Master Sheet'!$C$4:$C$12,MATCH(Table1[[#This Row],[Quantity]],'Master Sheet'!$B$4:$B$12,0)) -> 8 | N10: =Table1[[#This Row],[Quantity]]*Table1[[#This Row],[Unit Price]] -> 2614794 | O10: 0.2614794 | P10: =Table1[[#This Row],[Gross Amount]]*(1-(Table1[[#This Row],[Discount %]]/100)) -> 2405610.5 | Q10: =(Table1[[#This Row],[Gross Amount]]*(1-(Table1[[#This Row],[Discount %]]/100)))/10000000 -> 0.24056105 | R10: Paid | S10: {=IFERROR(_xlfn.IFS(Table1[[#This Row],[Payment Status]]="Partial","In Transit",Table1[[#This Row],[Payment Status]]="Paid","Delivered",Table1[[#This Row],[Payment Status]]="Pending","Pending"),"Invalid Input")} -> Delivered | T10: Valid | U10: {=IFERROR(_xlfn.IFS(Table1[[#This Row],[Payment Status]]="Partial","In Transit",Table1[[#This Row],[Payment Status]]="Paid","Completed",Table1[[#This Row],[Payment Status]]="Pending","Pending"),"Invalid Input")} -> Completed
A11: INV1009 | B11: 45619 | C11: Priya | D11: Mahadev | E11: Karnataka | F11: Mahadev Motors Karnataka | G11: Bengaluru | H11: =VLOOKUP(Table1[[#This Row],[City]],Table6[#All],2,FALSE) -> South | I11: Farmtrac 45 | J11: =_xlfn.XLOOKUP(Table1[[#This Row],[Tractor Model]],Table7[Product Model],Table7[Product Category],"Not Available",0) -> Farmtrac | K11: 3 | L11: 91771 | M11: =INDEX('Master Sheet'!$C$4:$C$12,MATCH(Table1[[#This Row],[Quantity]],'Master Sheet'!$B$4:$B$12,0)) -> 6 | N11: =Table1[[#This Row],[Quantity]]*Table1[[#This Row],[Unit Price]] -> 275313 | O11: 0.0275313 | P11: =Table1[[#This Row],[Gross Amount]]*(1-(Table1[[#This Row],[Discount %]]/100)) -> 258794.22 | Q11: =(Table1[[#This Row],[Gross Amount]]*(1-(Table1[[#This Row],[Discount %]]/100)))/10000000 -> 0.025879422 | R11: Paid | S11: {=IFERROR(_xlfn.IFS(Table1[[#This Row],[Payment Status]]="Partial","In Transit",Table1[[#This Row],[Payment Status]]="Paid","Delivered",Table1[[#This Row],[Payment Status]]="Pending","Pending"),"Invalid Input")} -> Delivered | T11: Invalid | U11: {=IFERROR(_xlfn.IFS(Table1[[#This Row],[Payment Status]]="Partial","In Transit",Table1[[#This Row],[Payment Status]]="Paid","Completed",Table1[[#This Row],[Payment Status]]="Pending","Pending"),"Invalid Input")} -> Completed
A12: INV1010 | B12: 45329 | C12: Neha | D12: Mahadev | E12: Uttar Pradesh | F12: Mahadev Motors Uttar Pradesh | G12: Lucknow | H12: =VLOOKUP(Table1[[#This Row],[City]],Table6[#All],2,FALSE) -> North | I12: Powertrac 439 | J12: =_xlfn.XLOOKUP(Table1[[#This Row],[Tractor Model]],Table7[Product Model],Table7[Product Category],"Not Available",0) -> Powertrac | K12: 1 | L12: 366788 | M12: =INDEX('Master Sheet'!$C$4:$C$12,MATCH(Table1[[#This Row],[Quantity]],'Master Sheet'!$B$4:$B$12,0)) -> 3 | N12: =Table1[[#This Row],[Quantity]]*Table1[[#This Row],[Unit Price]] -> 366788 | O12: 0.0366788 | P12: =Table1[[#This Row],[Gross Amount]]*(1-(Table1[[#This Row],[Discount %]]/100)) -> 355784.36 | Q12: =(Table1[[#This Row],[Gross Amount]]*(1-(Table1[[#This Row],[Discount %]]/100)))/10000000 -> 0.035578436 | R12: Partial | S12: {=IFERROR(_xlfn.IFS(Table1[[#This Row],[Payment Status]]="Partial","In Transit",Table1[[#This Row],[Payment Status]]="Paid","Delivered",Table1[[#This Row],[Payment Status]]="Pending","Pending"),"Invalid Input")} -> In Transit | T12: Valid | U12: {=IFERROR(_xlfn.IFS(Table1[[#This Row],[Payment Status]]="Partial","In Transit",Table1[[#This Row],[Payment Status]]="Paid","Completed",Table1[[#This Row],[Payment Status]]="Pending","Pending"),"Invalid Input")} -> In Transit
A13: INV1011 | B13: 45673 | C13: Rohit | D13: Kisan | E13: West Bengal | F13: Kisan Tractors West Bengal | G13: Kolkata | H13: =VLOOKUP(Table1[[#This Row],[City]],Table6[#All],2,FALSE) -> East | I13: Powertrac 439 | J13: =_xlfn.XLOOKUP(Table1[[#This Row],[Tractor Model]],Table7[Product Model],Table7[Product Category],"Not Available",0) -> Powertrac | K13: 8 | L13: 745852 | M13: =INDEX('Master Sheet'!$C$4:$C$12,MATCH(Table1[[#This Row],[Quantity]],'Master Sheet'!$B$4:$B$12,0)) -> 9 | N13: =Table1[[#This Row],[Quantity]]*Table1[[#This Row],[Unit Price]] -> 5966816 | O13: 0.5966816 | P13: =Table1[[#This Row],[Gross Amount]]*(1-(Table1[[#This Row],[Discount %]]/100)) -> 5429802.6 | Q13: =(Table1[[#This Row],[Gross Amount]]*(1-(Table1[[#This Row],[Discount %]]/100)))/10000000 -> 0.54298026 | R13: Paid | S13: {=IFERROR(_xlfn.IFS(Table1[[#This Row],[Payment Status]]="Partial","In Transit",Table1[[#This Row],[Payment Status]]="Paid","Delivered",Table1[[#This Row],[Payment Status]]="Pending","Pending"),"Invalid Input")} -> Delivered | T13: Invalid | U13: {=IFERROR(_xlfn.IFS(Table1[[#This Row],[Payment Status]]="Partial","In Transit",Table1[[#This Row],[Payment Status]]="Paid","Completed",Table1[[#This Row],[Payment Status]]="Pending","Pending"),"Invalid Input")} -> Completed
... A1980: INV2999 | B1980: 45506 | C1980: Vikas | D1980: Kisan | E1980: West Bengal | F1980: Kisan Tractors West Bengal | G1980: Kolkata | H1980: =VLOOKUP(Table1[[#This Row],[City]],Table6[#All],2,FALSE) -> East | I1980: Powertrac 439 | J1980: =_xlfn.XLOOKUP(Table1[[#This Row],[Tractor Model]],Table7[Product Model],Table7[Product Category],"Not Available",0) -> Powertrac | K1980: 4 | L1980: 223670 | M1980: =INDEX('Master Sheet'!$C$4:$C$12,MATCH(Table1[[#This Row],[Quantity]],'Master Sheet'!$B$4:$B$12,0)) -> 6 | N1980: =Table1[[#This Row],[Quantity]]*Table1[[#This Row],[Unit Price]] -> 894680 | O1980: 0.089468 | P1980: =Table1[[#This Row],[Gross Amount]]*(1-(Table1[[#This Row],[Discount %]]/100)) -> 840999.2 | Q1980: =(Table1[[#This Row],[Gross Amount]]*(1-(Table1[[#This Row],[Discount %]]/100)))/10000000 -> 0.08409992 | R1980: Paid | S1980: {=IFERROR(_xlfn.IFS(Table1[[#This Row],[Payment Status]]="Partial","In Transit",Table1[[#This Row],[Payment Status]]="Paid","Delivered",Table1[[#This Row],[Payment Status]]="Pending","Pending"),"Invalid Input")} -> Delivered | T1980: Invalid | U1980: {=IFERROR(_xlfn.IFS(Table1[[#This Row],[Payment Status]]="Partial","In Transit",Table1[[#This Row],[Payment Status]]="Paid","Completed",Table1[[#This Row],[Payment Status]]="Pending","Pending"),"Invalid Input")} -> Completed

Sheet Executive Sales Report
B2: Sum of Net Sales Amount | C2: Region | J2: Sum of Net Sales (Cr) | K2: Column Labels
B3: City | C3: East | D3: North | E3: South | F3: West | G3: Grand Total | J3: Row Labels | K3: East | L3: North | M3: South | N3: West | O3: Grand Total
B4: Bengaluru | E4: 6.7072791e+08 | G4: 6.7072791e+08 | J4: Bengaluru | M4: 67.072791 | O4: 67.072791
B5: Gurugram | D5: 7.7345772e+08 | G5: 7.7345772e+08 | J5: Gurugram | L5: 77.345772 | O5: 77.345772
B6: Kolkata | C6: 7.9348841e+08 | G6: 7.9348841e+08 | J6: Kolkata | K6: 79.348841 | O6: 79.348841
B7: Lucknow | D7: 7.8534235e+08 | G7: 7.8534235e+08 | J7: Lucknow | L7: 78.534235 | O7: 78.534235
B8: Pune | F8: 7.5501049e+08 | G8: 7.5501049e+08 | J8: Pune | N8: 75.501049 | O8: 75.501049
B9: Grand Total | C9: 7.9348841e+08 | D9: 1.5588001e+09 | E9: 6.7072791e+08 | F9: 7.5501049e+08 | G9: 3.7780269e+09 | J9: Grand Total | K9: 79.348841 | L9: 155.88001 | M9: 67.072791 | N9: 75.501049 | O9: 377.80269
B12: Orders Quantity By Dealers | C12: Quantity Sales By State
B13: Dealers Name | C13: Haryana | D13: Karnataka | E13: Maharashtra | F13: Uttar Pradesh | G13: West Bengal | H13: Grand Total
B14: Green Field | C14: 392 | D14: 290 | E14: 329 | F14: 390 | G14: 396 | H14: 1797
B15: Shakti | C15: 287 | D15: 329 | E15: 382 | F15: 353 | G15: 382 | H15: 1733
B16: Kisan | C16: 328 | D16: 348 | E16: 344 | F16: 391 | G16: 359 | H16: 1770
B17: Mahadev | C17: 343 | D17: 318 | E17: 334 | F17: 367 | G17: 366 | H17: 1728
B18: Agri | C18: 403 | D18: 302 | E18: 334 | F18: 308 | G18: 344 | H18: 1691
B19: Grand Total | C19: 1753 | D19: 1587 | E19: 1723 | F19: 1809 | G19: 1847 | H19: 8719
B22: Sales By Months | C22: Years
B23: Months | C23: 2024 | D23: 2025 | E23: Grand Total
B24: Jan | C24: 2.2843204e+08 | D24: 1.6866153e+08 | E24: 3.9709357e+08
B25: Feb | C25: 2.2387996e+08 | D25: 1.9479548e+08 | E25: 4.1867543e+08
B26: Mar | C26: 2.4408945e+08 | D26: 1.7687618e+08 | E26: 4.2096563e+08
B27: Apr | C27: 1.711359e+08 | D27: 2.0261889e+08 | E27: 3.7375479e+08
B28: May | C28: 1.9725482e+08 | D28: 2.0371792e+08 | E28: 4.0097274e+08
B29: Jun | C29: 1.885241e+08 | D29: 1.3760376e+08 | E29: 3.2612787e+08
B30: Grand Total | C30: 1.2533163e+09 | D30: 1.0842738e+09 | E30: 2.33759e+09
B33: Region | C33: Sum of Gross Amount | D33: Sum of Net Sales Amount | F33: Row Labels | G33: Sum of Gross Amount (Cr) | H33: Sum of Net Sales (Cr)
B34: East | C34: 859612610 | D34: 7.9348841e+08 | F34: East | G34: 85.961261 | H34: 79.348841
B35: North | C35: 1684832443 | D35: 1.5588001e+09 | F35: North | G35: 168.48324 | H35: 155.88001
B36: South | C36: 725339193 | D36: 6.7072791e+08 | F36: South | G36: 72.533919 | H36: 67.072791
B37: West | C37: 816612672 | D37: 7.5501049e+08 | F37: West | G37: 81.661267 | H37: 75.501049
B38: Grand Total | C38: 4086396918 | D38: 3.7780269e+09 | F38: Grand Total | G38: 408.63969 | H38: 377.80269
B41: Sum of Net Sales (Cr) | C41: Months
B42: Region | C42: East | D42: North | E42: South | F42: West | G42: Grand Total
B43: Jan | C43: 8.9398105 | D43: 15.025944 | E43: 6.9725885 | F43: 8.7710139 | G43: 39.709357
B44: Feb | C44: 8.7207542 | D44: 15.469876 | E44: 8.1903596 | F44: 9.4865531 | G44: 41.867543
B45: Mar | C45: 7.245783 | D45: 18.461116 | E45: 8.3464439 | F45: 8.0432205 | G45: 42.096563
B46: Apr | C46: 7.2304471 | D46: 16.38942 | E46: 5.7633444 | F46: 7.9922675 | G46: 37.375479
B47: May | C47: 7.137434 | D47: 17.436992 | E47: 7.9369194 | F47: 7.5859285 | G47: 40.097274
B48: Jun | C48: 5.5719658 | D48: 15.041575 | E48: 7.1944191 | F48: 4.8048267 | G48: 32.612787
B49: Jul | C49: 5.9330865 | D49: 8.6205536 | E49: 2.9898679 | F49: 4.9791118 | G49: 22.52262
...

Sheet Brand Sales Report
B2: Sum of Net Sales Amount | C2: Brand Name | H2: Sum of Net Sales (Cr) | I2: Column Labels
B3: Tractor Model Name | C3: Kubota | D3: Farmtrac | E3: Powertrac | F3: Grand Total | H3: Row Labels | I3: Kubota | J3: Farmtrac | K3: Powertrac | L3: Grand Total
B4: Kubota Mu4501 | C4: 7.7088347e+08 | F4: 7.7088347e+08 | H4: Kubota Mu4501 | I4: 77.088347 | L4: 77.088347
B5: Kubota Neostar | C5: 6.9232152e+08 | F5: 6.9232152e+08 | H5: Kubota Neostar | I5: 69.232152 | L5: 69.232152
B6: Farmtrac 60 | D6: 7.046158e+08 | F6: 7.046158e+08 | H6: Farmtrac 60 | J6: 70.46158 | L6: 70.46158
B7: Farmtrac 45 | D7: 7.5451749e+08 | F7: 7.5451749e+08 | H7: Farmtrac 45 | J7: 75.451749 | L7: 75.451749
B8: Powertrac 439 | E8: 8.556886e+08 | F8: 8.556886e+08 | H8: Powertrac 439 | K8: 85.56886 | L8: 85.56886
B9: Grand Total | C9: 1.463205e+09 | D9: 1.4591333e+09 | E9: 8.556886e+08 | F9: 3.7780269e+09 | H9: Grand Total | I9: 146.3205 | J9: 145.91333 | K9: 85.56886 | L9: 377.80269
B14: Sum of Quantity | C14: Model Name
B15: Region | C15: North | D15: East | E15: West | F15: South | G15: Grand Total
B16: Kubota Mu4501 | C16: 651 | D16: 371 | E16: 339 | F16: 397 | G16: 1758
B17: Kubota Neostar | C17: 694 | D17: 289 | E17: 291 | F17: 350 | G17: 1624
B18: Farmtrac 60 | C18: 708 | D18: 340 | E18: 329 | F18: 277 | G18: 1654
B19: Farmtrac 45 | C19: 745 | D19: 330 | E19: 409 | F19: 283 | G19: 1767
B20: Powertrac 439 | C20: 764 | D20: 517 | E20: 355 | F20: 280 | G20: 1916
B21: Grand Total | C21: 3562 | D21: 1847 | E21: 1723 | F21: 1587 | G21: 8719
B23: Sum of Net Sales Amount | C23: Model Name | J23: Sum of Net Sales (Cr) | K23: Column Labels
B24: Months | C24: Kubota Mu4501 | D24: Kubota Neostar | E24: Farmtrac 60 | F24: Farmtrac 45 | G24: Powertrac 439 | H24: Grand Total | J24: Row Labels | K24: Kubota Mu4501 | L24: Kubota Neostar | M24: Farmtrac 60 | N24: Farmtrac 45 | O24: Powertrac 439 | P24: Grand Total
B25: Jan | C25: 89184487 | D25: 90607022 | E25: 81032858 | F25: 71832025 | G25: 64437177 | H25: 3.9709357e+08 | J25: Jan | K25: 8.9184487 | L25: 9.0607022 | M25: 8.1032858 | N25: 7.1832025 | O25: 6.4437177 | P25: 39.709357
B26: Feb | C26: 94616034 | D26: 96491601 | E26: 59027769 | F26: 87761650 | G26: 80778380 | H26: 4.1867543e+08 | J26: Feb | K26: 9.4616034 | L26: 9.6491601 | M26: 5.9027769 | N26: 8.776165 | O26: 8.077838 | P26: 41.867543
B27: Mar | C27: 1.0071033e+08 | D27: 48218853 | E27: 71411025 | F27: 89900712 | G27: 1.1072471e+08 | H27: 4.2096563e+08 | J27: Mar | K27: 10.071033 | L27: 4.8218853 | M27: 7.1411025 | N27: 8.9900712 | O27: 11.072471 | P27: 42.096563
B28: Apr | C28: 66876066 | D28: 43134218 | E28: 79531475 | F28: 63464975 | G28: 1.2074806e+08 | H28: 3.7375479e+08 | J28: Apr | K28: 6.6876066 | L28: 4.3134218 | M28: 7.9531475 | N28: 6.3464975 | O28: 12.074806 | P28: 37.375479
B29: May | C29: 99517800 | D29: 95946952 | E29: 57726991 | F29: 65983517 | G29: 81797484 | H29: 4.0097274e+08 | J29: May | K29: 9.95178 | L29: 9.5946952 | M29: 5.7726991 | N29: 6.5983517 | O29: 8.1797484 | P29: 40.097274
B30: Jun | C30: 72242371 | D30: 47454721 | E30: 63459813 | F30: 67430388 | G30: 75540574 | H30: 3.2612787e+08 | J30: Jun | K30: 7.2242371 | L30: 4.7454721 | M30: 6.3459813 | N30: 6.7430388 | O30: 7.5540574 | P30: 32.612787
B31: Jul | C31: 17539547 | D31: 31845115 | E31: 61170837 | F31: 61735154 | G31: 52935544 | H31: 2.252262e+08 | J31: Jul | K31: 1.7539547 | L31: 3.1845115 | M31: 6.1170837 | N31: 6.1735154 | O31: 5.2935544 | P31: 22.52262
B32: Aug | C32: 44020811 | D32: 59448302 | E32: 39240013 | F32: 41646315 | G32: 51470553 | H32: 2.3582599e+08 | J32: Aug | K32: 4.4020811 | L32: 5.9448302 | M32: 3.9240013 | N32: 4.1646315 | O32: 5.1470553 | P32: 23.582599
B33: Sep | C33: 44758194 | D33: 50669629 | E33: 39089543 | F33: 53548721 | G33: 47350624 | H33: 2.3541671e+08 | J33: Sep | K33: 4.4758194 | L33: 5.0669629 | M33: 3.9089543 | N33: 5.3548721 | O33: 4.7350623 | P33: 23.541671
B34: Oct | C34: 43669030 | D34: 46322227 | E34: 56674240 | F34: 45804533 | G34: 35082514 | H34: 2.2755254e+08 | J34: Oct | K34: 4.366903 | L34: 4.6322227 | M34: 5.667424 | N34: 4.5804533 | O34: 3.5082514 | P34: 22.755254
B35: Nov | C35: 61251670 | D35: 44871995 | E35: 31193290 | F35: 64858130 | G35: 50607920 | H35: 2.52783e+08 | J35: Nov | K35: 6.125167 | L35: 4.4871995 | M35: 3.119329 | N35: 6.485813 | O35: 5.060792 | P35: 25.2783
B36: Dec | C36: 36497125 | D36: 37310885 | E36: 65057947 | F36: 40551372 | G36: 84215067 | H36: 2.636324e+08 | J36: Dec | K36: 3.6497125 | L36: 3.7310885 | M36: 6.5057947 | N36: 4.0551372 | O36: 8.4215067 | P36: 26.36324
B37: Grand Total | C37: 7.7088347e+08 | D37: 6.9232152e+08 | E37: 7.046158e+08 | F37: 7.5451749e+08 | G37: 8.556886e+08 | H37: 3.7780269e+09 | J37: Grand Total | K37: 77.088347 | L37: 69.232152 | M37: 70.46158 | N37: 75.451749 | O37: 85.56886 | P37: 377.80269
B40: Sum of Quantity | C40: Model Name
B41: Months | C41: Kubota | D41: Farmtrac | E41: Powertrac | F41: Grand Total | J41: Dealers Name | K41: Sum of Net Sales (Cr) | L41: Percentage of Net sales
B42: Jan | C42: 435 | D42: 375 | E42: 165 | F42: 975 | J42: Agri | K42: 70.991519 | L42: 0.18790634
B43: Feb | C43: 433 | D43: 341 | E43: 177 | F43: 951 | J43: Green Field | K43: 78.547505 | L43: 0.20790616
B44: Mar | C44: 332 | D44: 370 | E44: 220 | F44: 922 | J44: Kisan | K44: 77.553771 | L44: 0.20527586
B45: Apr | C45: 289 | D45: 322 | E45: 263 | F45: 874 | J45: Mahadev | K45: 79.482545 | L45: 0.2103811
B46: May | C46: 446 | D46: 318 | E46: 187 | F46: 951 | J46: Shakti | K46: 71.227348 | L46: 0.18853055
B47: Jun | C47: 271 | D47: 309 | E47: 183 | F47: 763 | J47: Grand Total | K47: 377.80269 | L47: 1
B48: Jul | C48: 117 | D48: 244 | E48: 119 | F48: 480
...

Sheet Brand Sales Dashboard
E2: Escorts Tractors Sales Performance Dashboard
E5: Net Sales Amount | G5: Net Quantity Sold | I5: Total Orders | K5: AOV | M5: Average Discount
E7: =GETPIVOTDATA("Net Sales (Cr)",'Executive Sales Report'!$J$2) -> 377.80269 | G7: =GETPIVOTDATA("Quantity",'Executive Sales Report'!$B$12) -> 8719 | I7: =GETPIVOTDATA("Invoice ID",'Executive Sales Report'!$B$58) -> 1979 | K7: =(GETPIVOTDATA("Net Sales Amount",'Executive Sales Report'!$B$2))/GETPIVOTDATA("Invoice ID",'Executive Sales Report'!$B$58) -> 1909058.6 | M7: =GETPIVOTDATA("Discount %",'Master Sheet'!$B$16) -> 6.482567

Sheet Executive Sales Dashboard
E1: Executive Sales Performance Dashboard
E4: Net Sales Amount | G4: Net Quantity Sold | I4: Total Orders | K4: AOV | M4: Average Discount
E6: =GETPIVOTDATA("Net Sales (Cr)",'Executive Sales Report'!$J$2) -> 377.80269 | G6: =GETPIVOTDATA("Quantity",'Executive Sales Report'!$B$12) -> 8719 | I6: =GETPIVOTDATA("Invoice ID",'Executive Sales Report'!$B$58) -> 1979 | K6: =(GETPIVOTDATA("Net Sales Amount",'Executive Sales Report'!$B$2))/GETPIVOTDATA("Invoice ID",'Executive Sales Report'!$B$58) -> 1909058.6 | M6: =GETPIVOTDATA("Discount %",'Master Sheet'!$B$16) -> 6.482567
